Workbook
Name Beta: 'Summary-2010'!$B$55

Sheet 1990
B1: Network Speed (congested) [km/h] | C1: Network Speed (freeflow) [km/h] | D1: Circuity [ ] | E1: Average Airline Speed [km/h] | F1: Airline Radius [km] | G1: Area covered in 30 mins [km2] | H1: Urbanized area density [people/km2] | I1: Urbanized Area [km2] | J1: Population | K1: Accessibility | L1: MinPA,P | M1: . | N1: Employment Density | O1: Employment | P1: Employment Accessibility | Q1: Min EA, E
A2: Area | B2: S_n | D2: C1 | E2: S_a | F2: R_a | G2: A_30 | H2: D_UA | L2: =MIN(J2,K2) -> 0 | M2: .
A3: Atlanta | B3: 60.375468 | C3: 63.997996 | D3: 1.2804196 | E3: =B3/D3 -> 47.152878 | F3: =E3*0.5 -> 23.576439 | G3: =PI()*F3^2 -> 1746.2495 | H3: =J3/I3 -> 964.67391 | I3: 2944 | J3: 2840000 | K3: =G3*H3 -> 1684561.3 | L3: =MIN(J3,K3) -> 1684561.3 | M3: . | N3: =O3/I3 -> 503.32235 | O3: 1481781 | P3: =G3*N3 -> 878926.38 | Q3: =MIN(P3,O3) -> 878926.38
A4: Austin* | B4: 63.478689 | C4: 67.922197 | D4: 1.3588387 | E4: =B4/D4 -> 46.715398 | F4: =E4*0.5 -> 23.357699 | G4: =PI()*F4^2 -> 1713.9968 | H4: =J4/I4 -> 932.86219 | I4: 707.5 | J4: 660000 | K4: =G4*H4 -> 1598922.8 | L4: =MIN(J4,K4) -> 660000 | M4: . | N4: =O4/I4 -> 571.04735 | O4: 404016 | P4: =G4*N4 -> 978773.3 | Q4: =MIN(P4,O4) -> 404016
A5: Baltimore | B5: 60.37745 | C5: 64.603872 | D5: 1.252585 | E5: =B5/D5 -> 48.202277 | F5: =E5*0.5 -> 24.101139 | G5: =PI()*F5^2 -> 1824.8408 | H5: =J5/I5 -> 1296.8394 | I5: 1534.5 | J5: 1990000 | K5: =G5*H5 -> 2366525.4 | L5: =MIN(J5,K5) -> 1990000 | M5: . | N5: =O5/I5 -> 776.6784 | O5: 1191813 | P5: =G5*N5 -> 1417314.5 | Q5: =MIN(P5,O5) -> 1191813
A6: Boston | B6: 61.541691 | C6: 67.69586 | D6: 1.2423921 | E6: =B6/D6 -> 49.534838 | F6: =E6*0.5 -> 24.767419 | G6: =PI()*F6^2 -> 1927.1316 | H6: =J6/I6 -> 1563.9893 | I6: 2308.2 | J6: 3610000 | K6: =G6*H6 -> 3014013.1 | L6: =MIN(J6,K6) -> 3014013.1 | M6: . | N6: =O6/I6 -> 927.87323 | O6: 2141717 | P6: =G6*N6 -> 1788133.8 | Q6: =MIN(P6,O6) -> 1788133.8
A7: Buffalo | B7: 73.276598 | C7: 76.207662 | D7: 1.2197721 | E7: =B7/D7 -> 60.074008 | F7: =E7*0.5 -> 30.037004 | G7: =PI()*F7^2 -> 2834.4127 | H7: =J7/I7 -> 1440.1623 | I7: 739.5 | J7: 1065000 | K7: =G7*H7 -> 4082014.3 | L7: =MIN(J7,K7) -> 1065000 | M7: . | N7: =O7/I7 -> 718.21771 | O7: 531122 | P7: =G7*N7 -> 2035725.4 | Q7: =MIN(P7,O7) -> 531122
A8: Charlotte | B8: 66.908177 | C8: 71.591749 | D8: 1.2963499 | E8: =B8/D8 -> 51.612743 | F8: =E8*0.5 -> 25.806372 | G8: =PI()*F8^2 -> 2092.2027 | H8: =J8/I8 -> 862.48203 | I8: 626.1 | J8: 540000 | K8: =G8*H8 -> 1804487.3 | L8: =MIN(J8,K8) -> 540000 | M8: . | N8: =O8/I8 -> 966.06932 | O8: 604856 | P8: =G8*N8 -> 2021212.9 | Q8: =MIN(P8,O8) -> 604856
A9: Chicago | B9: 59.830535 | C9: 64.616977 | D9: 1.2306496 | E9: =B9/D9 -> 48.617034 | F9: =E9*0.5 -> 24.308517 | G9: =PI()*F9^2 -> 1856.3797 | H9: =J9/I9 -> 1830.0112 | I9: 4103.8 | J9: 7510000 | K9: =G9*H9 -> 3397195.6 | L9: =MIN(J9,K9) -> 3397195.6 | M9: . | N9: =O9/I9 -> 936.04391 | O9: 3841337 | P9: =G9*N9 -> 1737652.9 | Q9: =MIN(P9,O9) -> 1737652.9
A10: Cincinnati | B10: 67.518821 | C10: 74.270703 | D10: 1.3292592 | E10: =B10/D10 -> 50.794323 | F10: =E10*0.5 -> 25.397161 | G10: =PI()*F10^2 -> 2026.3769 | H10: =J10/I10 -> 860.24751 | I10: 1325.2 | J10: 1140000 | K10: =G10*H10 -> 1743185.7 | L10: =MIN(J10,K10) -> 1140000 | M10: . | N10: =O10/I10 -> 613.31573 | O10: 812766 | P10: =G10*N10 -> 1242808.8 | Q10: =MIN(P10,O10) -> 812766
A11: Cleveland | B11: 70.270148 | C11: 77.297163 | D11: 1.2049847 | E11: =B11/D11 -> 58.316215 | F11: =E11*0.5 -> 29.158108 | G11: =PI()*F11^2 -> 2670.9671 | H11: =J11/I11 -> 1068.6096 | I11: 1647 | J11: 1760000 | K11: =G11*H11 -> 2854221.1 | L11: =MIN(J11,K11) -> 1760000 | M11: . | N11: =O11/I11 -> 754.15847 | O11: 1242099 | P11: =G11*N11 -> 2014332.5 | Q11: =MIN(P11,O11) -> 1242099
A12: Columbus | B12: 67.725933 | C12: 77.207564 | D12: 1.2627799 | E12: =B12/D12 -> 53.632411 | F12: =E12*0.5 -> 26.816206 | G12: =PI()*F12^2 -> 2259.1472 | H12: =J12/I12 -> 973.91694 | I12: 893.3 | J12: 870000 | K12: =G12*H12 -> 2200221.7 | L12: =MIN(J12,K12) -> 870000 | M12: . | N12: =O12/I12 -> 758.8257 | O12: 677859 | P12: =G12*N12 -> 1714299 | Q12: =MIN(P12,O12) -> 677859
A13: Dallas-Fort Worth | B13: 66.031469 | C13: 76.596505 | D13: 1.3065071 | E13: =B13/D13 -> 50.540461 | F13: =E13*0.5 -> 25.27023 | G13: =PI()*F13^2 -> 2006.1725 | H13: =J13/I13 -> 869.56522 | I13: 3737.5 | J13: 3250000 | K13: =G13*H13 -> 1744497.8 | L13: =MIN(J13,K13) -> 1744497.8 | M13: . | N13: =O13/I13 -> 528.85779 | O13: 1976606 | P13: =G13*N13 -> 1060980 | Q13: =MIN(P13,O13) -> 1060980
A14: Denver | B14: 65.002141 | C14: 76.052505 | D14: 1.3654163 | E14: =B14/D14 -> 47.606098 | F14: =E14*0.5 -> 23.803049 | G14: =PI()*F14^2 -> 1779.9797 | H14: =J14/I14 -> 1329.5187 | I14: 1188.4 | J14: 1580000 | K14: =G14*H14 -> 2366516.3 | L14: =MIN(J14,K14) -> 1580000 | M14: . | N14: =O14/I14 -> 811.94211 | O14: 964912 | P14: =G14*N14 -> 1445240.5 | Q14: =MIN(P14,O14) -> 964912
A15: Detroit | B15: 59.740127 | C15: 69.895948 | D15: 1.2288146 | E15: =B15/D15 -> 48.616062 | F15: =E15*0.5 -> 24.308031 | G15: =PI()*F15^2 -> 1856.3055 | H15: =J15/I15 -> 1369.2488 | I15: 2899.4 | J15: 3970000 | K15: =G15*H15 -> 2541744.1 | L15: =MIN(J15,K15) -> 2541744.1 | M15: . | N15: =O15/I15 -> 717.34842 | O15: 2079880 | P15: =G15*N15 -> 1331617.8 | Q15: =MIN(P15,O15) -> 1331617.8
A16: Grand Rapids*2 | B16: 70.939381 | C16: 83.70847 | D16: 1.2825248 | E16: =B16/D16 -> 55.312286 | F16: =E16*0.5 -> 27.656143 | G16: =PI()*F16^2 -> 2402.8856 | H16: =J16/I16 -> 1190.5898 | I16: 578.2 | J16: 688399 | K16: =G16*H16 -> 2860851 | L16: =MIN(J16,K16) -> 688399 | M16: . | N16: =O16/I16 -> 693.86026 | O16: =337335+63855 -> 401190 | P16: =G16*N16 -> 1667266.8 | Q16: =MIN(P16,O16) -> 401190
A17: Hampton Roads | B17: 64.898649 | C17: 85.666217 | D17: 1.3571401 | E17: =B17/D17 -> 47.820155 | F17: =E17*0.5 -> 23.910078 | G17: =PI()*F17^2 -> 1796.0228 | H17: =J17/I17 -> 770.84182 | I17: 1718.9 | J17: 1325000 | K17: =G17*H17 -> 1384449.5 | L17: =MIN(J17,K17) -> 1325000 | M17: . | N17: =O17/I17 -> 406.65484 | O17: 698999 | P17: =G17*N17 -> 730361.36 | Q17: =MIN(P17,O17) -> 698999
A18: Hartford | B18: 70.550118 | C18: 84.660141 | D18: 1.3223702 | E18: =B18/D18 -> 53.351261 | F18: =E18*0.5 -> 26.675631 | G18: =PI()*F18^2 -> 2235.5236 | H18: =J18/I18 -> 1320.2112 | I18: 624.9 | J18: 825000 | K18: =G18*H18 -> 2951363.4 | L18: =MIN(J18,K18) -> 825000 | M18: . | N18: =O18/I18 -> 899.29429 | O18: 561969 | P18: =G18*N18 -> 2010393.6 | Q18: =MIN(P18,O18) -> 561969
A19: Honolulu*2 | B19: 61.851771 | C19: 73.603607 | D19: 1.3847021 | E19: =B19/D19 -> 44.667925 | F19: =E19*0.5 -> 22.333962 | G19: =PI()*F19^2 -> 1567.0449 | H19: =J19/I19 -> 2328.0373 | I19: 359.2 | J19: 836231 | K19: =G19*H19 -> 3648138.9 | L19: =MIN(J19,K19) -> 836231 | M19: . | N19: =O19/I19 -> 1218.0345 | O19: 437518 | P19: =G19*N19 -> 1908714.7 | Q19: =MIN(P19,O19) -> 437518
A20: Houston | B20: 61.86593 | C20: 73.620457 | D20: 1.3197846 | E20: =B20/D20 -> 46.875778 | F20: =E20*0.5 -> 23.437889 | G20: =PI()*F20^2 -> 1725.7856 | H20: =J20/I20 -> 951.03794 | I20: 3049.3 | J20: 2900000 | K20: =G20*H20 -> 1641287.6 | L20: =MIN(J20,K20) -> 1641287.6 | M20: . | N20: =O20/I20 -> 577.11475 | O20: 1759796 | P20: =G20*N20 -> 995976.35 | Q20: =MIN(P20,O20) -> 995976.35
A21: Indianapolis | B21: 66.181817 | C21: 78.094544 | D21: 1.2722485 | E21: =B21/D21 -> 52.019567 | F21: =E21*0.5 -> 26.009784 | G21: =PI()*F21^2 -> 2125.3152 | H21: =J21/I21 -> 778.16206 | I21: 1214.4 | J21: 945000 | K21: =G21*H21 -> 1653839.6 | L21: =MIN(J21,K21) -> 945000 | M21: . | N21: =O21/I21 -> 514.63356 | O21: 624971 | P21: =G21*N21 -> 1093758.5 | Q21: =MIN(P21,O21) -> 624971
A22: Inland Empire** | B22: 65.102211 | C22: 72.914476 | D22: 1.3359338 | E22: =B22/D22 -> 48.731614 | F22: =E22*0.5 -> 24.365807 | G22: =PI()*F22^2 -> 1865.1401 | H22: =J22/I22 -> 1078.382 | I22: 1191.6 | J22: 1285000 | K22: =G22*H22 -> 2011333.6 | L22: =MIN(J22,K22) -> 1285000 | M22: . | N22: =O22/I22 -> 643.63293 | O22: 766953 | P22: =G22*N22 -> 1200465.6 | Q22: =MIN(P22,O22) -> 766953
A23: Jacksonville* | B23: 55.540281 | C23: 57.20649 | D23: 1.3671479 | E23: =B23/D23 -> 40.624926 | F23: =E23*0.5 -> 20.312463 | G23: =PI()*F23^2 -> 1296.209 | H23: =J23/I23 -> 547.57016 | I23: 1314.9 | J23: 720000 | K23: =G23*H23 -> 709765.38 | L23: =MIN(J23,K23) -> 709765.38 | M23: . | N23: =O23/I23 -> 337.57852 | O23: 443882 | P23: =G23*N23 -> 437572.33 | Q23: =MIN(P23,O23) -> 437572.33
A24: Kansas City | B24: 63.219918 | C24: 65.116516 | D24: 1.2881189 | E24: =B24/D24 -> 49.079255 | F24: =E24*0.5 -> 24.539628 | G24: =PI()*F24^2 -> 1891.8461 | H24: =J24/I24 -> 587.90735 | I24: 1973.1 | J24: 1160000 | K24: =G24*H24 -> 1112230.2 | L24: =MIN(J24,K24) -> 1112230.2 | M24: . | N24: =O24/I24 -> 390.91227 | O24: 771309 | P24: =G24*N24 -> 739545.86 | Q24: =MIN(P24,O24) -> 739545.86
A25: Las Vegas* | B25: 58.291698 | C25: 60.040449 | D25: 1.3334071 | E25: =B25/D25 -> 43.716355 | F25: =E25*0.5 -> 21.858178 | G25: =PI()*F25^2 -> 1500.9899 | H25: =J25/I25 -> 1175.4828 | I25: 595.5 | J25: 700000 | K25: =G25*H25 -> 1764387.8 | L25: =MIN(J25,K25) -> 700000 | M25: . | N25: =O25/I25 -> 623.22082 | O25: 371128 | P25: =G25*N25 -> 935448.18 | Q25: =MIN(P25,O25) -> 371128
A26: Los Angeles | B26: 48.116228 | C26: 49.559715 | D26: 1.2467602 | E26: =B26/D26 -> 38.59301 | F26: =E26*0.5 -> 19.296505 | G26: =PI()*F26^2 -> 1169.7881 | H26: =J26/I26 -> 2243.0421 | I26: 5091.3 | J26: 11420000 | K26: =G26*H26 -> 2623883.9 | L26: =MIN(J26,K26) -> 2623883.9 | M26: . | N26: =O26/I26 -> 1337.3879 | O26: 6809043 | P26: =G26*N26 -> 1564460.4 | Q26: =MIN(P26,O26) -> 1564460.4
A27: Louisville* | B27: 62.487213 | C27: 64.986701 | D27: 1.3589322 | E27: =B27/D27 -> 45.982583 | F27: =E27*0.5 -> 22.991292 | G27: =PI()*F27^2 -> 1660.6443 | H27: =J27/I27 -> 1106.8598 | I27: 731.8 | J27: 810000 | K27: =G27*H27 -> 1838100.4 | L27: =MIN(J27,K27) -> 810000 | M27: . | N27: =O27/I27 -> 610.65318 | O27: 446876 | P27: =G27*N27 -> 1014077.7 | Q27: =MIN(P27,O27) -> 446876
A28: Memphis* | B28: 65.308032 | C28: 67.920353 | D28: 1.331226 | E28: =B28/D28 -> 49.058562 | F28: =E28*0.5 -> 24.529281 | G28: =PI()*F28^2 -> 1890.2511 | H28: =J28/I28 -> 973.62165 | I28: 883.3 | J28: 860000 | K28: =G28*H28 -> 1840389.4 | L28: =MIN(J28,K28) -> 860000 | M28: . | N28: =O28/I28 -> 507.45726 | O28: 448237 | P28: =G28*N28 -> 959221.65 | Q28: =MIN(P28,O28) -> 448237
... A53: Washington | B53: 57.166397 | C53: 76.031308 | D53: 1.3152548 | E53: =B53/D53 -> 43.464123 | F53: =E53*0.5 -> 21.732062 | G53: =PI()*F53^2 -> 1483.7193 | H53: =J53/I53 -> 1267.0645 | I53: 2446.6 | J53: 3100000 | K53: =G53*H53 -> 1879968 | L53: =MIN(J53,K53) -> 1879968 | M53: . | N53: =O53/I53 -> 905.07235 | O53: 2214350 | P53: =G53*N53 -> 1342873.3 | Q53: =MIN(P53,O53) -> 1342873.3
A55: Notes:
A56: 1 Circuity is from a sample of OD points with network distance matched to average commute distance
A57: 2 Population from 1990 Census
A58: * Circuity is based on either 1995 or 2001 commute distance; 1990 commute distance not available
A59: ** Uses 1995 Employment
A60: Data Sources:
A61: Network Speed (congested), Network Speed (freeflow), Population: TTI complete data 1982-2007 (calculated from 1990 values only)
A62: Circuity: Networks are Census Tiger 2008 county-level shapefiles merged together, commute distances are from 1990 NPTS
A63: Urbanized Area: Census 1990 Population and Housing Unit Counts (census.gov)
A64: Employment: Census 1990, sum of responses to question P050. Travel Time to Work: Workers 16 years and over (American FactFinder)

Sheet 1995
B1: Network Speed (congested) [km/h] | C1: Network Speed (freeflow) [km/h] | D1: Circuity [ ] | E1: Average Airline Speed [km/h] | F1: Airline Radius [km] | G1: Area covered in 30 mins [km2] | H1: Urbanized area density [people/km2] | I1: Area [km2] | J1: Population | K1: Accessibility | L1: MinPA,P | M1: . | N1: Employment Density | O1: Employment | P1: Employment Accessibility | Q1: Min EA, E
A2: Area | B2: S_n | D2: C1 | E2: S_a | F2: R_a | G2: A_30 | H2: D_UA | L2: =MIN(J2,K2) -> 0 | M2: .
A3: Atlanta | B3: 57.036474 | C3: 70.725228 | D3: 1.2545032 | E3: =B3/D3 -> 45.465387 | F3: =E3*0.5 -> 22.732694 | G3: =PI()*F3^2 -> 1623.4977 | H3: =J3/I3 -> 1103.9402 | I3: 2944 | J3: 3250000 | K3: =G3*H3 -> 1792244.4 | L3: =MIN(J3,K3) -> 1792244.4 | M3: . | N3: =O3/I3 -> 643.62636 | O3: 1894836 | P3: =G3*N3 -> 1044925.9 | Q3: =MIN(P3,O3) -> 1044925.9
A4: Austin* | B4: 62.912833 | C4: 73.608014 | D4: 1.3588387 | E4: =B4/D4 -> 46.298972 | F4: =E4*0.5 -> 23.149486 | G4: =PI()*F4^2 -> 1683.5754 | H4: =J4/I4 -> 1074.2049 | I4: 707.5 | J4: 760000 | K4: =G4*H4 -> 1808505 | L4: =MIN(J4,K4) -> 760000 | M4: . | N4: =O4/I4 -> 678.06502 | O4: 479731 | P4: =G4*N4 -> 1141573.6 | Q4: =MIN(P4,O4) -> 479731
A5: Baltimore | B5: 60.832586 | C5: 72.390778 | D5: 1.252585 | E5: =B5/D5 -> 48.565634 | F5: =E5*0.5 -> 24.282817 | G5: =PI()*F5^2 -> 1852.4565 | H5: =J5/I5 -> 1394.5911 | I5: 1534.5 | J5: 2140000 | K5: =G5*H5 -> 2583419.3 | L5: =MIN(J5,K5) -> 2140000 | M5: . | N5: =O5/I5 -> 646.30108 | O5: 991749 | P5: =G5*N5 -> 1197244.6 | Q5: =MIN(P5,O5) -> 991749
A6: Boston | B6: 59.830799 | C6: 71.198651 | D6: 1.2257226 | E6: =B6/D6 -> 48.812674 | F6: =E6*0.5 -> 24.406337 | G6: =PI()*F6^2 -> 1871.3502 | H6: =J6/I6 -> 1594.3159 | I6: 2308.2 | J6: 3680000 | K6: =G6*H6 -> 2983523.4 | L6: =MIN(J6,K6) -> 2983523.4 | M6: . | N6: =O6/I6 -> 1247.0938 | O6: 2878542 | P6: =G6*N6 -> 2333749.3 | Q6: =MIN(P6,O6) -> 2333749.3
A7: Buffalo | B7: 66.3074 | C7: 68.959696 | D7: 1.2376013 | E7: =B7/D7 -> 53.57735 | F7: =E7*0.5 -> 26.788675 | G7: =PI()*F7^2 -> 2254.5109 | H7: =J7/I7 -> 1446.9236 | I7: 739.5 | J7: 1070000 | K7: =G7*H7 -> 3262105 | L7: =MIN(J7,K7) -> 1070000 | M7: . | N7: =O7/I7 -> 630.65585 | O7: 466370 | P7: =G7*N7 -> 1421820.5 | Q7: =MIN(P7,O7) -> 466370
A8: Charlotte | B8: 61.905551 | C8: 69.953273 | D8: 1.2806694 | E8: =B8/D8 -> 48.338432 | F8: =E8*0.5 -> 24.169216 | G8: =PI()*F8^2 -> 1835.1645 | H8: =J8/I8 -> 1054.1447 | I8: 626.1 | J8: 660000 | K8: =G8*H8 -> 1934528.9 | L8: =MIN(J8,K8) -> 660000 | M8: . | N8: =O8/I8 -> 1161.0174 | O8: 726913 | P8: =G8*N8 -> 2130657.9 | Q8: =MIN(P8,O8) -> 726913
A9: Chicago | B9: 54.90711 | C9: 71.379243 | D9: 1.2306496 | E9: =B9/D9 -> 44.616363 | F9: =E9*0.5 -> 22.308182 | G9: =PI()*F9^2 -> 1563.4292 | H9: =J9/I9 -> 1887.2752 | I9: 4103.8 | J9: 7745000 | K9: =G9*H9 -> 2950621.2 | L9: =MIN(J9,K9) -> 2950621.2 | M9: . | N9: =O9/I9 -> 977.85272 | O9: =3741075+224929+46908 -> 4012912 | P9: =G9*N9 -> 1528803.5 | Q9: =MIN(P9,O9) -> 1528803.5
A10: Cincinnati | B10: 64.694239 | C10: 75.045318 | D10: 1.3292592 | E10: =B10/D10 -> 48.669394 | F10: =E10*0.5 -> 24.334697 | G10: =PI()*F10^2 -> 1860.3804 | H10: =J10/I10 -> 980.984 | I10: 1325.2 | J10: 1300000 | K10: =G10*H10 -> 1825003.4 | L10: =MIN(J10,K10) -> 1300000 | M10: . | N10: =O10/I10 -> 673.15801 | O10: =789795+102274 -> 892069 | P10: =G10*N10 -> 1252330 | Q10: =MIN(P10,O10) -> 892069
A11: Cleveland | B11: 68.272477 | C11: 75.78245 | D11: 1.2227035 | E11: =B11/D11 -> 55.837312 | F11: =E11*0.5 -> 27.918656 | G11: =PI()*F11^2 -> 2448.7187 | H11: =J11/I11 -> 1074.6812 | I11: 1647 | J11: 1770000 | K11: =G11*H11 -> 2631592 | L11: =MIN(J11,K11) -> 1770000 | M11: . | N11: =O11/I11 -> 633.32848 | O11: 1043092 | P11: =G11*N11 -> 1550843.3 | Q11: =MIN(P11,O11) -> 1043092
A12: Columbus | B12: 64.21199 | C12: 73.843788 | D12: 1.2387292 | E12: =B12/D12 -> 51.836988 | F12: =E12*0.5 -> 25.918494 | G12: =PI()*F12^2 -> 2110.4224 | H12: =J12/I12 -> 1130.6392 | I12: 893.3 | J12: 1010000 | K12: =G12*H12 -> 2386126.3 | L12: =MIN(J12,K12) -> 1010000 | M12: . | N12: =O12/I12 -> 810.5295 | O12: 724046 | P12: =G12*N12 -> 1710559.6 | Q12: =MIN(P12,O12) -> 724046
A13: Dallas-Fort Worth | B13: 62.831555 | C13: 72.884604 | D13: 1.2669463 | E13: =B13/D13 -> 49.592911 | F13: =E13*0.5 -> 24.796456 | G13: =PI()*F13^2 -> 1931.6529 | H13: =J13/I13 -> 936.45485 | I13: 3737.5 | J13: 3500000 | K13: =G13*H13 -> 1808905.7 | L13: =MIN(J13,K13) -> 1808905.7 | M13: . | N13: =O13/I13 -> 638.19746 | O13: =1747902+637361 -> 2385263 | P13: =G13*N13 -> 1232776 | Q13: =MIN(P13,O13) -> 1232776
A14: Denver | B14: 57.288368 | C14: 69.891808 | D14: 1.3381636 | E14: =B14/D14 -> 42.811183 | F14: =E14*0.5 -> 21.405592 | G14: =PI()*F14^2 -> 1439.4757 | H14: =J14/I14 -> 1455.7388 | I14: 1188.4 | J14: 1730000 | K14: =G14*H14 -> 2095500.6 | L14: =MIN(J14,K14) -> 1730000 | M14: . | N14: =O14/I14 -> 816.15113 | O14: 969914 | P14: =G14*N14 -> 1174829.7 | Q14: =MIN(P14,O14) -> 969914
A15: Detroit | B15: 53.475546 | C15: 67.379188 | D15: 1.239001 | E15: =B15/D15 -> 43.160214 | F15: =E15*0.5 -> 21.580107 | G15: =PI()*F15^2 -> 1463.0429 | H15: =J15/I15 -> 1384.7693 | I15: 2899.4 | J15: 4015000 | K15: =G15*H15 -> 2025976.8 | L15: =MIN(J15,K15) -> 2025976.8 | M15: . | N15: =O15/I15 -> 664.662 | O15: 1927121 | P15: =G15*N15 -> 972429 | Q15: =MIN(P15,O15) -> 972429
A16: Grand Rapids* | B16: 60.555305 | C16: 66.005283 | D16: 1.2825248 | E16: =B16/D16 -> 47.215698 | F16: =E16*0.5 -> 23.607849 | G16: =PI()*F16^2 -> 1750.9055 | H16: =J16/I16 -> 830.16257 | I16: 578.2 | J16: 480000 | K16: =G16*H16 -> 1453536.2 | L16: =MIN(J16,K16) -> 480000 | M16: . | N16: =O16/I16 -> 892.0339 | O16: 515774 | P16: =G16*N16 -> 1561867 | Q16: =MIN(P16,O16) -> 515774
A17: Hampton Roads | B17: 59.158545 | C17: 68.032326 | D17: 1.3437943 | E17: =B17/D17 -> 44.023514 | F17: =E17*0.5 -> 22.011757 | G17: =PI()*F17^2 -> 1522.1564 | H17: =J17/I17 -> 823.20088 | I17: 1718.9 | J17: 1415000 | K17: =G17*H17 -> 1253040.5 | L17: =MIN(J17,K17) -> 1253040.5 | M17: . | N17: =O17/I17 -> 318.17034 | O17: 546903 | P17: =G17*N17 -> 484305.03 | Q17: =MIN(P17,O17) -> 484305.03
A18: Hartford | B18: 70.476777 | C18: 76.11492 | D18: 1.3223702 | E18: =B18/D18 -> 53.2958 | F18: =E18*0.5 -> 26.6479 | G18: =PI()*F18^2 -> 2230.8782 | H18: =J18/I18 -> 1344.2151 | I18: 624.9 | J18: 840000 | K18: =G18*H18 -> 2998780.1 | L18: =MIN(J18,K18) -> 840000 | M18: . | N18: =O18/I18 -> 872.53321 | O18: 545246 | P18: =G18*N18 -> 1946515.3 | Q18: =MIN(P18,O18) -> 545246
A19: Honolulu* | B19: 62.589105 | C19: 75.732818 | D19: 1.3847021 | E19: =B19/D19 -> 45.200411 | F19: =E19*0.5 -> 22.600205 | G19: =PI()*F19^2 -> 1604.629 | H19: =J19/I19 -> 1948.7751 | I19: 359.2 | J19: 700000 | K19: =G19*H19 -> 3127061 | L19: =MIN(J19,K19) -> 700000 | M19: . | N19: =O19/I19 -> 861.60078 | O19: 309487 | P19: =G19*N19 -> 1382549.6 | Q19: =MIN(P19,O19) -> 309487
A20: Houston | B20: 61.72194 | C20: 73.449109 | D20: 1.3274916 | E20: =B20/D20 -> 46.495165 | F20: =E20*0.5 -> 23.247582 | G20: =PI()*F20^2 -> 1697.874 | H20: =J20/I20 -> 996.95012 | I20: 3049.3 | J20: 3040000 | K20: =G20*H20 -> 1692695.7 | L20: =MIN(J20,K20) -> 1692695.7 | M20: . | N20: =O20/I20 -> 577.52173 | O20: 1761037 | P20: =G20*N20 -> 980559.14 | Q20: =MIN(P20,O20) -> 980559.14
A21: Indianapolis | B21: 56.481833 | C21: 70.037473 | D21: 1.2722485 | E21: =B21/D21 -> 44.395284 | F21: =E21*0.5 -> 22.197642 | G21: =PI()*F21^2 -> 1547.9736 | H21: =J21/I21 -> 811.10013 | I21: 1214.4 | J21: 985000 | K21: =G21*H21 -> 1255561.6 | L21: =MIN(J21,K21) -> 985000 | M21: . | N21: =O21/I21 -> 628.12912 | O21: 762800 | P21: =G21*N21 -> 972327.29 | Q21: =MIN(P21,O21) -> 762800
A22: Inland Empire | B22: 63.440181 | C22: 74.225012 | D22: 1.3453292 | E22: =B22/D22 -> 47.15588 | F22: =E22*0.5 -> 23.57794 | G22: =PI()*F22^2 -> 1746.4718 | H22: =J22/I22 -> 1191.6751 | I22: 1191.6 | J22: 1420000 | K22: =G22*H22 -> 2081226.9 | L22: =MIN(J22,K22) -> 1420000 | M22: . | N22: =O22/I22 -> 643.63293 | O22: 766953 | P22: =G22*N22 -> 1124086.8 | Q22: =MIN(P22,O22) -> 766953
A23: Jacksonville* | B23: 57.215795 | C23: 68.658954 | D23: 1.3671479 | E23: =B23/D23 -> 41.85048 | F23: =E23*0.5 -> 20.92524 | G23: =PI()*F23^2 -> 1375.5955 | H23: =J23/I23 -> 612.21386 | I23: 1314.9 | J23: 805000 | K23: =G23*H23 -> 842158.66 | L23: =MIN(J23,K23) -> 805000 | M23: . | N23: =O23/I23 -> 349.42505 | O23: 459459 | P23: =G23*N23 -> 480667.55 | Q23: =MIN(P23,O23) -> 459459
A24: Kansas City | B24: 68.436669 | C24: 73.227236 | D24: 1.282665 | E24: =B24/D24 -> 53.355062 | F24: =E24*0.5 -> 26.677531 | G24: =PI()*F24^2 -> 2235.8421 | H24: =J24/I24 -> 674.06619 | I24: 1973.1 | J24: 1330000 | K24: =G24*H24 -> 1507105.6 | L24: =MIN(J24,K24) -> 1330000 | M24: . | N24: =O24/I24 -> 418.47397 | O24: 825691 | P24: =G24*N24 -> 935641.74 | Q24: =MIN(P24,O24) -> 825691
A25: Las Vegas | B25: 52.889872 | C25: 65.583442 | D25: 1.3334071 | E25: =B25/D25 -> 39.66521 | F25: =E25*0.5 -> 19.832605 | G25: =PI()*F25^2 -> 1235.6896 | H25: =J25/I25 -> 1595.2981 | I25: 595.5 | J25: 950000 | K25: =G25*H25 -> 1971293.3 | L25: =MIN(J25,K25) -> 950000 | M25: . | N25: =O25/I25 -> 983.45256 | O25: 585646 | P25: =G25*N25 -> 1215242.1 | Q25: =MIN(P25,O25) -> 585646
A26: Los Angeles | B26: 50.562417 | C26: 71.798632 | D26: 1.2409046 | E26: =B26/D26 -> 40.746416 | F26: =E26*0.5 -> 20.373208 | G26: =PI()*F26^2 -> 1303.9734 | H26: =J26/I26 -> 2374.6391 | I26: 5091.3 | J26: 12090000 | K26: =G26*H26 -> 3096466.1 | L26: =MIN(J26,K26) -> 3096466.1 | M26: . | N26: =O26/I26 -> 975.70581 | O26: =3693537+1274074 -> 4967611 | P26: =G26*N26 -> 1272294.4 | Q26: =MIN(P26,O26) -> 1272294.4
A27: Louisville* | B27: 61.310499 | C27: 71.120178 | D27: 1.3589322 | E27: =B27/D27 -> 45.116672 | F27: =E27*0.5 -> 22.558336 | G27: =PI()*F27^2 -> 1598.689 | H27: =J27/I27 -> 1127.3572 | I27: 731.8 | J27: 825000 | K27: =G27*H27 -> 1802293.6 | L27: =MIN(J27,K27) -> 825000 | M27: . | N27: =O27/I27 -> 674.68844 | O27: 493737 | P27: =G27*N27 -> 1078617 | Q27: =MIN(P27,O27) -> 493737
A28: Memphis | B28: 58.655633 | C28: 65.107753 | D28: 1.331226 | E28: =B28/D28 -> 44.061364 | F28: =E28*0.5 -> 22.030682 | G28: =PI()*F28^2 -> 1524.775 | H28: =J28/I28 -> 1052.8699 | I28: 883.3 | J28: 930000 | K28: =G28*H28 -> 1605389.7 | L28: =MIN(J28,K28) -> 930000 | M28: . | N28: =O28/I28 -> 578.7275 | O28: 511190 | P28: =G28*N28 -> 882429.21 | Q28: =MIN(P28,O28) -> 511190
A29: Milwaukee | B29: 59.418221 | C29: 67.14259 | D29: 1.2176021 | E29: =B29/D29 -> 48.799376 | F29: =E29*0.5 -> 24.399688 | G29: =PI()*F29^2 -> 1870.3308 | H29: =J29/I29 -> 942.68477 | I29: 1326 | J29: 1250000 | K29: =G29*H29 -> 1763132.3 | L29: =MIN(J29,K29) -> 1250000 | M29: . | N29: =O29/I29 -> 580.19759 | O29: 769342 | P29: =G29*N29 -> 1085161.4 | Q29: =MIN(P29,O29) -> 769342
A30: Minneapolis-St.Paul | B30: 61.666325 | C30: 72.1496 | D30: 1.2383391 | E30: =B30/D30 -> 49.797608 | F30: =E30*0.5 -> 24.898804 | G30: =PI()*F30^2 -> 1947.6317 | H30: =J30/I30 -> 806.36374 | I30: 2753.1 | J30: 2220000 | K30: =G30*H30 -> 1570499.6 | L30: =MIN(J30,K30) -> 1570499.6 | M30: . | N30: =O30/I30 -> 558.99059 | O30: 1538957 | P30: =G30*N30 -> 1088707.8 | Q30: =MIN(P30,O30) -> 1088707.8
A31: Nashville | B31: 63.173996 | C31: 71.386616 | D31: 1.3533327 | E31: =B31/D31 -> 46.680315 | F31: =E31*0.5 -> 23.340157 | G31: =PI()*F31^2 -> 1711.4233 | H31: =J31/I31 -> 511.10046 | I31: 1252.2 | J31: 640000 | K31: =G31*H31 -> 874709.22 | L31: =MIN(J31,K31) -> 640000 | M31: . | N31: =O31/I31 -> 488.76777 | O31: 612035 | P31: =G31*N31 -> 836488.53 | Q31: =MIN(P31,O31) -> 612035
A32: New Orleans | B32: 58.965102 | C32: 67.809867 | D32: 1.3763526 | E32: =B32/D32 -> 42.841567 | F32: =E32*0.5 -> 21.420784 | G32: =PI()*F32^2 -> 1441.5197 | H32: =J32/I32 -> 1551.1079 | I32: 699.5 | J32: 1085000 | K32: =G32*H32 -> 2235952.6 | L32: =MIN(J32,K32) -> 1085000 | M32: . | N32: =O32/I32 -> 763.52538 | O32: 534086 | P32: =G32*N32 -> 1100636.9 | Q32: =MIN(P32,O32) -> 534086
A33: New York | B33: 58.662283 | C33: 72.154609 | D33: 1.2603547 | E33: =B33/D33 -> 46.544265 | F33: =E33*0.5 -> 23.272132 | G33: =PI()*F33^2 -> 1701.4619 | H33: =J33/I33 -> 2117.6348 | I33: 7683.1 | J33: 16270000 | K33: =G33*H33 -> 3603074.9 | L33: =MIN(J33,K33) -> 3603074.9 | M33: . | N33: =O33/I33 -> 958.84916 | O33: =3557965+617736+210152+305726+1019809+895963+759583 -> 7366934 | P33: =G33*N33 -> 1631445.3 | Q33: =MIN(P33,O33) -> 1631445.3
A34: Oklahoma City | B34: 65.428156 | C34: 70.008126 | D34: 1.2964578 | E34: =B34/D34 -> 50.466863 | F34: =E34*0.5 -> 25.233431 | G34: =PI()*F34^2 -> 2000.3339 | H34: =J34/I34 -> 447.68101 | I34: 1675.3 | J34: 750000 | K34: =G34*H34 -> 895511.51 | L34: =MIN(J34,K34) -> 750000 | M34: . | N34: =O34/I34 -> 254.5365 | O34: 426425 | P34: =G34*N34 -> 509157.99 | Q34: =MIN(P34,O34) -> 426425
A35: Orlando | B35: 51.610671 | C35: 65.029445 | D35: 1.3247336 | E35: =B35/D35 -> 38.959283 | F35: =E35*0.5 -> 19.479641 | G35: =PI()*F35^2 -> 1192.0975 | H35: =J35/I35 -> 1012.6211 | I35: 1022.1 | J35: 1035000 | K35: =G35*H35 -> 1207143.1 | L35: =MIN(J35,K35) -> 1035000 | M35: . | N35: =O35/I35 -> 729.77693 | O35: 745905 | P35: =G35*N35 -> 869965.28 | Q35: =MIN(P35,O35) -> 745905
A36: Philadelphia | B36: 57.527408 | C36: 67.307067 | D36: 1.2151793 | E36: =B36/D36 -> 47.340674 | F36: =E36*0.5 -> 23.670337 | G36: =PI()*F36^2 -> 1760.1868 | H36: =J36/I36 -> 1548.768 | I36: 3015.3 | J36: 4670000 | K36: =G36*H36 -> 2726120.9 | L36: =MIN(J36,K36) -> 2726120.9 | M36: . | N36: =O36/I36 -> 794.65194 | O36: =2112593+283521 -> 2396114 | P36: =G36*N36 -> 1398735.9 | Q36: =MIN(P36,O36) -> 1398735.9
A37: Phoenix | B37: 55.217531 | C37: 64.604512 | D37: 1.3855039 | E37: =B37/D37 -> 39.853755 | F37: =E37*0.5 -> 19.926878 | G37: =PI()*F37^2 -> 1247.465 | H37: =J37/I37 -> 1156.6114 | I37: 1919.4 | J37: 2220000 | K37: =G37*H37 -> 1442832.3 | L37: =MIN(J37,K37) -> 1442832.3 | M37: . | N37: =O37/I37 -> 663.90487 | O37: 1274299 | P37: =G37*N37 -> 828198.1 | Q37: =MIN(P37,O37) -> 828198.1
A38: Pittsburgh | B38: 60.206378 | C38: 66.227016 | D38: 1.3073565 | E38: =B38/D38 -> 46.051996 | F38: =E38*0.5 -> 23.025998 | G38: =PI()*F38^2 -> 1665.6617 | H38: =J38/I38 -> 880.80588 | I38: 2015.2 | J38: 1775000 | K38: =G38*H38 -> 1467124.6 | L38: =MIN(J38,K38) -> 1467124.6 | M38: . | N38: =O38/I38 -> 499.64371 | O38: 1006882 | P38: =G38*N38 -> 832237.37 | Q38: =MIN(P38,O38) -> 832237.37
A39: Portland | B39: 60.024289 | C39: 72.029147 | D39: 1.4034944 | E39: =B39/D39 -> 42.767743 | F39: =E39*0.5 -> 21.383871 | G39: =PI()*F39^2 -> 1436.5559 | H39: =J39/I39 -> 1323.5148 | I39: 1004.9 | J39: 1330000 | K39: =G39*H39 -> 1901303 | L39: =MIN(J39,K39) -> 1330000 | M39: . | N39: =O39/I39 -> 831.47477 | O39: 835549 | P39: =G39*N39 -> 1194460 | Q39: =MIN(P39,O39) -> 835549
A40: Providence* | B40: 67.445743 | C40: 72.841403 | D40: 1.2391401 | E40: =B40/D40 -> 54.429474 | F40: =E40*0.5 -> 27.214737 | G40: =PI()*F40^2 -> 2326.7951 | H40: =J40/I40 -> 1480.0931 | I40: 773.6 | J40: 1145000 | K40: =G40*H40 -> 3443873.4 | L40: =MIN(J40,K40) -> 1145000 | M40: . | N40: =O40/I40 -> 485.89452 | O40: 375888 | P40: =G40*N40 -> 1130577 | Q40: =MIN(P40,O40) -> 375888
...

Sheet 2001
B1: Network Speed (congested) [km/h] | C1: Network Speed (freeflow) [km/h] | D1: Circuity [ ] | E1: Average Airline Speed [km/h] | F1: Airline Radius [km] | G1: Area covered in 30 mins [km2] | H1: Urbanized area density [people/km2] | I1: Urbanized Area [km2] | J1: Population | K1: Accessibility | L1: MinPA,P | M1: . | N1: Employment Density | O1: Employment | P1: Employment Accessibility | Q1: Min EA, E
A2: Area | B2: S_n | D2: C2 | E2: S_a | F2: R_a | G2: A_30 | H2: D_UA | L2: =MIN(J2,K2) -> 0 | Q2: =MIN(P2,O2) -> 0
A3: Atlanta | B3: 52.31679 | C3: 68.53499 | D3: 1.2545032 | E3: =B3/D3 -> 41.703194 | F3: =E3*0.5 -> 20.851597 | G3: =PI()*F3^2 -> 1365.9302 | H3: 540.543 | I3: 5083.0589 | J3: 3850000 | K3: =G3*H3 -> 738344.01 | L3: =MIN(J3,K3) -> 738344.01 | M3: . | N3: =O3/I3 -> 418.87927 | O3: 2129188 | P3: =G3*N3 -> 572159.85 | Q3: =MIN(P3,O3) -> 572159.85
A4: Austin | B4: 53.19888 | C4: 67.56258 | D4: 1.3588387 | E4: =B4/D4 -> 39.150255 | F4: =E4*0.5 -> 19.575128 | G4: =PI()*F4^2 -> 1203.8131 | H4: 741.3162 | I4: 823.94448 | J4: 960000 | K4: =G4*H4 -> 892406.17 | L4: =MIN(J4,K4) -> 892406.17 | M4: . | N4: =O4/I4 -> 704.51955 | O4: 580485 | P4: =G4*N4 -> 848109.88 | Q4: =MIN(P4,O4) -> 580485
A5: Baltimore | B5: 57.5626 | C5: 71.37762 | D5: 1.252585 | E5: =B5/D5 -> 45.955044 | F5: =E5*0.5 -> 22.977522 | G5: =PI()*F5^2 -> 1658.6557 | H5: 1130.18 | I5: 1768.2607 | J5: 2210000 | K5: =G5*H5 -> 1874579.5 | L5: =MIN(J5,K5) -> 1874579.5 | M5: . | N5: =O5/I5 -> 601.54252 | O5: 1063684 | P5: =G5*N5 -> 997751.95 | Q5: =MIN(P5,O5) -> 997751.95
A6: Boston | B6: 60.28802 | C6: 74.15427 | D6: 1.2192841 | E6: =B6/D6 -> 49.445425 | F6: =E6*0.5 -> 24.722712 | G6: =PI()*F6^2 -> 1920.1807 | H6: 780.1243 | I6: 4496.6741 | J6: 3940000 | K6: =G6*H6 -> 1497979.6 | L6: =MIN(J6,K6) -> 1497979.6 | M6: . | N6: =O6/I6 -> 683.91236 | O6: 3075331 | P6: =G6*N6 -> 1313235.3 | Q6: =MIN(P6,O6) -> 1313235.3
A7: Buffalo | B7: 60.07548 | C7: 64.28076 | D7: 1.2197721 | E7: =B7/D7 -> 49.251397 | F7: =E7*0.5 -> 24.625699 | G7: =PI()*F7^2 -> 1905.1404 | H7: 742.2481 | I7: 949.73302 | J7: 1115000 | K7: =G7*H7 -> 1414086.9 | L7: =MIN(J7,K7) -> 1115000 | M7: . | N7: =O7/I7 -> 500.80074 | O7: 475627 | P7: =G7*N7 -> 954095.74 | Q7: =MIN(P7,O7) -> 475627
A8: Charlotte | B8: 54.73937 | C8: 66.78204 | D8: 1.232499 | E8: =B8/D8 -> 44.413317 | F8: =E8*0.5 -> 22.206659 | G8: =PI()*F8^2 -> 1549.2314 | H8: 612.8043 | I8: 1126.4161 | J8: 865000 | K8: =G8*H8 -> 949375.69 | L8: =MIN(J8,K8) -> 865000 | M8: . | N8: =O8/I8 -> 720.43269 | O8: 811507 | P8: =G8*N8 -> 1116117 | Q8: =MIN(P8,O8) -> 811507
A9: Chicago | B9: 47.50277 | C9: 64.12874 | D9: 1.2285083 | E9: =B9/D9 -> 38.667032 | F9: =E9*0.5 -> 19.333516 | G9: =PI()*F9^2 -> 1174.2797 | H9: 1111.92 | I9: 5498.057 | J9: 8150000 | K9: =G9*H9 -> 1305705.1 | L9: =MIN(J9,K9) -> 1305705.1 | M9: . | N9: =O9/I9 -> 762.04903 | O9: =3915405+225650+48734 -> 4189789 | P9: =G9*N9 -> 894858.73 | Q9: =MIN(P9,O9) -> 894858.73
A10: Cincinnati | B10: 59.70134 | C10: 70.44758 | D10: 1.3292592 | E10: =B10/D10 -> 44.913242 | F10: =E10*0.5 -> 22.456621 | G10: =PI()*F10^2 -> 1584.3046 | H10: 725.1187 | I10: 1739.8649 | J10: 1540000 | K10: =G10*H10 -> 1148808.9 | L10: =MIN(J10,K10) -> 1148808.9 | M10: . | N10: =O10/I10 -> 537.37105 | O10: =820201+114752 -> 934953 | P10: =G10*N10 -> 851359.42 | Q10: =MIN(P10,O10) -> 851359.42
A11: Cleveland | B11: 62.77554 | C11: 69.05309 | D11: 1.1958825 | E11: =B11/D11 -> 52.493067 | F11: =E11*0.5 -> 26.246533 | G11: =PI()*F11^2 -> 2164.182 | H11: 820.467 | I11: 1675.7263 | J11: 1785000 | K11: =G11*H11 -> 1775639.9 | L11: =MIN(J11,K11) -> 1775639.9 | M11: . | N11: =O11/I11 -> 643.10978 | O11: 1077676 | P11: =G11*N11 -> 1391806.6 | Q11: =MIN(P11,O11) -> 1077676
A12: Columbus | B12: 60.79675 | C12: 71.13219 | D12: 1.2517998 | E12: =B12/D12 -> 48.56747 | F12: =E12*0.5 -> 24.283735 | G12: =PI()*F12^2 -> 1852.5965 | H12: 793.0747 | I12: 1030.0578 | J12: 1140000 | K12: =G12*H12 -> 1469247.4 | L12: =MIN(J12,K12) -> 1140000 | M12: . | N12: =O12/I12 -> 750.93647 | O12: 773508 | P12: =G12*N12 -> 1391182.3 | Q12: =MIN(P12,O12) -> 773508
A13: Dallas-Fort Worth | B13: 56.96404 | C13: 70.06577 | D13: 1.2688045 | E13: =B13/D13 -> 44.895839 | F13: =E13*0.5 -> 22.447919 | G13: =PI()*F13^2 -> 1583.0771 | H13: 831.1357 | I13: 3644.2179 | J13: 4090000 | K13: =G13*H13 -> 1315751.9 | L13: =MIN(J13,K13) -> 1315751.9 | M13: . | N13: =O13/I13 -> 713.75617 | O13: =1915132+685951 -> 2601083 | P13: =G13*N13 -> 1129931 | Q13: =MIN(P13,O13) -> 1129931
A14: Denver | B14: 50.87279 | C14: 67.15208 | D14: 1.3463144 | E14: =B14/D14 -> 37.786709 | F14: =E14*0.5 -> 18.893354 | G14: =PI()*F14^2 -> 1121.4193 | H14: 919.8315 | I14: 1291.906 | J14: 2025000 | K14: =G14*H14 -> 1031516.8 | L14: =MIN(J14,K14) -> 1031516.8 | M14: . | N14: =O14/I14 -> 836.36813 | O14: 1080509 | P14: =G14*N14 -> 937919.34 | Q14: =MIN(P14,O14) -> 937919.34
A15: Detroit | B15: 50.51411 | C15: 65.16321 | D15: 1.2231188 | E15: =B15/D15 -> 41.299429 | F15: =E15*0.5 -> 20.649715 | G15: =PI()*F15^2 -> 1339.6088 | H15: 1127.53 | I15: 3267.1409 | J15: 4030000 | K15: =G15*H15 -> 1510449.1 | L15: =MIN(J15,K15) -> 1510449.1 | M15: . | N15: =O15/I15 -> 597.8524 | O15: 1953268 | P15: =G15*N15 -> 800888.31 | Q15: =MIN(P15,O15) -> 800888.31
A16: Grand Rapids | B16: 56.839146 | C16: 63.091452 | D16: 1.2876333 | E16: =B16/D16 -> 44.142338 | F16: =E16*0.5 -> 22.071169 | G16: =PI()*F16^2 -> 1530.3844 | H16: 1048.9459 | I16: 666.54415 | J16: 555000 | K16: =G16*H16 -> 1605290.6 | L16: =MIN(J16,K16) -> 555000 | M16: . | N16: =O16/I16 -> 796.59389 | O16: 530965 | P16: =G16*N16 -> 1219094.9 | Q16: =MIN(P16,O16) -> 530965
A17: Hampton Roads | B17: 54.51603 | C17: 64.32891 | D17: 1.3149722 | E17: =B17/D17 -> 41.457935 | F17: =E17*0.5 -> 20.728967 | G17: =PI()*F17^2 -> 1349.9112 | H17: 595.8125 | I17: 1364.4099 | J17: 1520000 | K17: =G17*H17 -> 804293.97 | L17: =MIN(J17,K17) -> 804293.97 | M17: . | N17: =O17/I17 -> 420.42645 | O17: 573634 | P17: =G17*N17 -> 567538.38 | Q17: =MIN(P17,O17) -> 567538.38
A18: Hartford | B18: 68.56857 | C18: 75.42543 | D18: 1.318605 | E18: =B18/D18 -> 52.000843 | F18: =E18*0.5 -> 26.000422 | G18: =PI()*F18^2 -> 2123.7855 | H18: 616.3466 | I18: 1215.5915 | J18: 870000 | K18: =G18*H18 -> 1308988 | L18: =MIN(J18,K18) -> 870000 | M18: . | N18: =O18/I18 -> 467.19724 | O18: 567921 | P18: =G18*N18 -> 992226.72 | Q18: =MIN(P18,O18) -> 567921
A19: Honolulu | B19: 58.403203 | C19: 68.915779 | D19: 1.5656731 | E19: =B19/D19 -> 37.302297 | F19: =E19*0.5 -> 18.651149 | G19: =PI()*F19^2 -> 1092.8512 | H19: 1930.5094 | I19: 399.17986 | J19: 700000 | K19: =G19*H19 -> 2109759.5 | L19: =MIN(J19,K19) -> 700000 | M19: . | N19: =O19/I19 -> 802.79853 | O19: 320461 | P19: =G19*N19 -> 877339.34 | Q19: =MIN(P19,O19) -> 320461
A20: Houston | B20: 53.7673 | C20: 68.82214 | D20: 1.3120577 | E20: =B20/D20 -> 40.979371 | F20: =E20*0.5 -> 20.489685 | G20: =PI()*F20^2 -> 1318.9261 | H20: 778.6393 | I20: 3354.7213 | J20: 3630000 | K20: =G20*H20 -> 1026967.7 | L20: =MIN(J20,K20) -> 1026967.7 | M20: . | N20: =O20/I20 -> 557.65586 | O20: 1870780 | P20: =G20*N20 -> 735506.84 | Q20: =MIN(P20,O20) -> 735506.84
A21: Indianapolis | B21: 53.33619 | C21: 65.07016 | D21: 1.2553195 | E21: =B21/D21 -> 42.488138 | F21: =E21*0.5 -> 21.244069 | G21: =PI()*F21^2 -> 1417.8337 | H21: 795.3705 | I21: 1432.0576 | J21: 1030000 | K21: =G21*H21 -> 1127703.1 | L21: =MIN(J21,K21) -> 1030000 | M21: . | N21: =O21/I21 -> 568.0393 | O21: 813465 | P21: =G21*N21 -> 805385.24 | Q21: =MIN(P21,O21) -> 805385.24
A22: Inland Empire1 | B22: 57.81975 | C22: 71.69648 | D22: 1.3322188 | E22: =B22/D22 -> 43.401092 | F22: =E22*0.5 -> 21.700546 | G22: =PI()*F22^2 -> 1479.419 | H22: 1048.911 | I22: 1136.4228 | J22: 1630000 | K22: =G22*H22 -> 1551778.9 | L22: =MIN(J22,K22) -> 1551778.9 | M22: . | N22: =O22/I22 -> 772.15541 | O22: 877495 | P22: =G22*N22 -> 1142341.4 | Q22: =MIN(P22,O22) -> 877495
A23: Jacksonville | B23: 54.3979 | C23: 63.64554 | D23: 1.3671479 | E23: =B23/D23 -> 39.789331 | F23: =E23*0.5 -> 19.894666 | G23: =PI()*F23^2 -> 1243.4352 | H23: 464.3661 | I23: 1063.2316 | J23: 890000 | K23: =G23*H23 -> 577409.15 | L23: =MIN(J23,K23) -> 577409.15 | M23: . | N23: =O23/I23 -> 467.65164 | O23: 497222 | P23: =G23*N23 -> 581494.5 | Q23: =MIN(P23,O23) -> 497222
A24: Kansas City | B24: 63.34106 | C24: 69.04175 | D24: 1.3058059 | E24: =B24/D24 -> 48.507255 | F24: =E24*0.5 -> 24.253628 | G24: =PI()*F24^2 -> 1848.0056 | H24: 534.1705 | I24: 1513.627 | J24: 1425000 | K24: =G24*H24 -> 987150.07 | L24: =MIN(J24,K24) -> 987150.07 | M24: . | N24: =O24/I24 -> 588.92447 | O24: 891412 | P24: =G24*N24 -> 1088335.7 | Q24: =MIN(P24,O24) -> 891412
A25: Las Vegas | B25: 50.76474 | C25: 64.47121 | D25: 1.3395993 | E25: =B25/D25 -> 37.895466 | F25: =E25*0.5 -> 18.947733 | G25: =PI()*F25^2 -> 1127.8839 | H25: 1701.467 | I25: 740.49811 | J25: 1300000 | K25: =G25*H25 -> 1919057.2 | L25: =MIN(J25,K25) -> 1300000 | M25: . | N25: =O25/I25 -> 934.33729 | O25: 691875 | P25: =G25*N25 -> 1053824 | Q25: =MIN(P25,O25) -> 691875
A26: Los Angeles | B26: 47.96656 | C26: 70.9905 | D26: 1.3322188 | E26: =B26/D26 -> 36.005017 | F26: =E26*0.5 -> 18.002509 | G26: =PI()*F26^2 -> 1018.1598 | H26: 2155.593 | I26: 4319.9303 | J26: 12450000 | K26: =G26*H26 -> 2194738.1 | L26: =MIN(J26,K26) -> 2194738.1 | M26: . | N26: =O26/I26 -> 1226.6024 | O26: =3889686+1409151 -> 5298837 | P26: =G26*N26 -> 1248877.2 | Q26: =MIN(P26,O26) -> 1248877.2
A27: Louisville | B27: 57.96375 | C27: 68.97688 | D27: 1.3589322 | E27: =B27/D27 -> 42.653894 | F27: =E27*0.5 -> 21.326947 | G27: =PI()*F27^2 -> 1428.9178 | H27: 763.3284 | I27: 1013.4551 | J27: 860000 | K27: =G27*H27 -> 1090733.6 | L27: =MIN(J27,K27) -> 860000 | M27: . | N27: =O27/I27 -> 509.17498 | O27: 516026 | P27: =G27*N27 -> 727569.21 | Q27: =MIN(P27,O27) -> 516026
A28: Memphis | B28: 57.32139 | C28: 64.77317 | D28: 1.3251324 | E28: =B28/D28 -> 43.257105 | F28: =E28*0.5 -> 21.628553 | G28: =PI()*F28^2 -> 1469.6191 | H28: 772.2043 | I28: 1035.5225 | J28: 980000 | K28: =G28*H28 -> 1134846.2 | L28: =MIN(J28,K28) -> 980000 | M28: . | N28: =O28/I28 -> 519.02878 | O28: 537466 | P28: =G28*N28 -> 762774.61 | Q28: =MIN(P28,O28) -> 537466
A29: Milwaukee | B29: 57.25628 | C29: 65.84471 | D29: 1.2147109 | E29: =B29/D29 -> 47.135727 | F29: =E29*0.5 -> 23.567864 | G29: =PI()*F29^2 -> 1744.9794 | H29: 931.9707 | I29: 1261.4412 | J29: 1400000 | K29: =G29*H29 -> 1626269.7 | L29: =MIN(J29,K29) -> 1400000 | M29: . | N29: =O29/I29 -> 619.65949 | O29: 781664 | P29: =G29*N29 -> 1081293 | Q29: =MIN(P29,O29) -> 781664
A30: Minneapolis-St.Paul | B30: 55.30265 | C30: 69.68134 | D30: 1.2298335 | E30: =B30/D30 -> 44.967592 | F30: =E30*0.5 -> 22.483796 | G30: =PI()*F30^2 -> 1588.1413 | H30: 756.6357 | I30: 2316.0156 | J30: 2430000 | K30: =G30*H30 -> 1201644.4 | L30: =MIN(J30,K30) -> 1201644.4 | M30: . | N30: =O30/I30 -> 709.14809 | O30: 1642398 | P30: =G30*N30 -> 1126227.4 | Q30: =MIN(P30,O30) -> 1126227.4
A31: Nashville | B31: 60.80458 | C31: 70.53332 | D31: 1.3726075 | E31: =B31/D31 -> 44.298592 | F31: =E31*0.5 -> 22.149296 | G31: =PI()*F31^2 -> 1541.2381 | H31: 455.8151 | I31: 1115.6883 | J31: 850000 | K31: =G31*H31 -> 702519.59 | L31: =MIN(J31,K31) -> 702519.59 | M31: . | N31: =O31/I31 -> 568.951 | O31: 634772 | P31: =G31*N31 -> 876888.95 | Q31: =MIN(P31,O31) -> 634772
A32: New Orleans | B32: 56.71207 | C32: 65.21888 | D32: 1.3418186 | E32: =B32/D32 -> 42.265079 | F32: =E32*0.5 -> 21.13254 | G32: =PI()*F32^2 -> 1402.9857 | H32: 1342.165 | I32: 512.39266 | J32: 1095000 | K32: =G32*H32 -> 1883038.3 | L32: =MIN(J32,K32) -> 1095000 | M32: . | N32: =O32/I32 -> 1056.4398 | O32: 541312 | P32: =G32*N32 -> 1482170 | Q32: =MIN(P32,O32) -> 541312
A33: New York | B33: 51.8687 | C33: 66.91063 | D33: 1.2505759 | E33: =B33/D33 -> 41.47585 | F33: =E33*0.5 -> 20.737925 | G33: =PI()*F33^2 -> 1351.0782 | H33: 1475.768 | I33: 8683.2033 | J33: 17200000 | K33: =G33*H33 -> 1993877.9 | L33: =MIN(J33,K33) -> 1993877.9 | M33: . | N33: =O33/I33 -> 908.0232 | O33: =3845734+647143+223496+331771+1100827+943220+792359 -> 7884550 | P33: =G33*N33 -> 1226810.3 | Q33: =MIN(P33,O33) -> 1226810.3
A34: Oklahoma City | B34: 59.51772 | C34: 65.46949 | D34: 1.2823721 | E34: =B34/D34 -> 46.412207 | F34: =E34*0.5 -> 23.206104 | G34: =PI()*F34^2 -> 1691.8207 | H34: 584.5659 | I34: 834.88805 | J34: 810000 | K34: =G34*H34 -> 988980.68 | L34: =MIN(J34,K34) -> 810000 | M34: . | N34: =O34/I34 -> 528.7128 | O34: 441416 | P34: =G34*N34 -> 894487.26 | Q34: =MIN(P34,O34) -> 441416
A35: Orlando | B35: 45.74069 | C35: 60.83512 | D35: 1.323813 | E35: =B35/D35 -> 34.552229 | F35: =E35*0.5 -> 17.276115 | G35: =PI()*F35^2 -> 937.65273 | H35: 708.8145 | I35: 1173.7605 | J35: 1230000 | K35: =G35*H35 -> 664621.85 | L35: =MIN(J35,K35) -> 664621.85 | M35: . | N35: =O35/I35 -> 697.01275 | O35: 818126 | P35: =G35*N35 -> 653555.91 | Q35: =MIN(P35,O35) -> 653555.91
A36: Philadelphia | B36: 52.86588 | C36: 66.61101 | D36: 1.2151793 | E36: =B36/D36 -> 43.504592 | F36: =E36*0.5 -> 21.752296 | G36: =PI()*F36^2 -> 1486.4835 | H36: 942.2731 | I36: 4660.7165 | J36: 5125000 | K36: =G36*H36 -> 1400673.4 | L36: =MIN(J36,K36) -> 1400673.4 | M36: . | N36: =O36/I36 -> 547.27079 | O36: =2237898+312776 -> 2550674 | P36: =G36*N36 -> 813508.99 | Q36: =MIN(P36,O36) -> 813508.99
A37: Phoenix | B37: 52.44265 | C37: 67.12659 | D37: 1.3591592 | E37: =B37/D37 -> 38.584626 | F37: =E37*0.5 -> 19.292313 | G37: =PI()*F37^2 -> 1169.2799 | H37: 990.8817 | I37: 2069.4187 | J37: 2900000 | K37: =G37*H37 -> 1158618 | L37: =MIN(J37,K37) -> 1158618 | M37: . | N37: =O37/I37 -> 677.88603 | O37: 1402830 | P37: =G37*N37 -> 792638.48 | Q37: =MIN(P37,O37) -> 792638.48
A38: Pittsburgh | B38: 58.55113 | C38: 64.40624 | D38: 1.3100772 | E38: =B38/D38 -> 44.692884 | F38: =E38*0.5 -> 22.346442 | G38: =PI()*F38^2 -> 1568.7966 | H38: 603.0711 | I38: 2207.6966 | J38: 1765000 | K38: =G38*H38 -> 946095.89 | L38: =MIN(J38,K38) -> 946095.89 | M38: . | N38: =O38/I38 -> 470.46366 | O38: 1038641 | P38: =G38*N38 -> 738061.78 | Q38: =MIN(P38,O38) -> 738061.78
A39: Portland | B39: 53.08795 | C39: 67.95258 | D39: 1.3917707 | E39: =B39/D39 -> 38.144179 | F39: =E39*0.5 -> 19.072089 | G39: =PI()*F39^2 -> 1142.7373 | H39: 1192.044 | I39: 1227.5103 | J39: 1590000 | K39: =G39*H39 -> 1362193.2 | L39: =MIN(J39,K39) -> 1362193.2 | M39: . | N39: =O39/I39 -> 714.74674 | O39: 877359 | P39: =G39*N39 -> 816767.78 | Q39: =MIN(P39,O39) -> 816767.78
A40: Providence | B40: 62.4824 | C40: 71.22993 | D40: 1.2391401 | E40: =B40/D40 -> 50.424 | F40: =E40*0.5 -> 25.212 | G40: =PI()*F40^2 -> 1996.9375 | H40: 595.1384 | I40: 1304.4013 | J40: 1210000 | K40: =G40*H40 -> 1188454.2 | L40: =MIN(J40,K40) -> 1188454.2 | M40: . | N40: =O40/I40 -> 482.4474 | O40: 629305 | P40: =G40*N40 -> 963417.29 | Q40: =MIN(P40,O40) -> 629305
...

Sheet 2010-10
A1: =1/6 -> 0.16666667 | B1: Network Speed (congested) [km/h] | C1: Network Speed (freeflow) [km/h] | D1: 10 Minute Distance | E1: Circuity [ ] | F1: Average Airline Speed [km/h] | G1: Airline Radius [km] | H1: Area covered in $A$1$ hrs [km2] | I1: Urbanized area density [people/km2] | J1: Area [km2] | K1: Population | L1: Accessibility | M1: MinPA,P | N1: . | O1: Employment Density | P1: Employment | Q1: Employment Accessibility | R1: Min EA, E
A2: Area | B2: S_n | C2: S_f | E2: C3 | F2: S_a | G2: R_a | H2: A_X | I2: D_UA | J2: Area | K2: Pop | L2: A_P | M2: MinA_P | N2: . | O2: D_Emp | P2: Emp | Q2: A_E | R2: MinA_E
A3: Atlanta | B3: 57.43675 | C3: 68.14325 | D3: =C3*$A$1*1000 -> 11357.208 | E3: ='Interval Circuities'!B3 -> 1.3810679 | F3: =B3/E3 -> 41.58865 | G3: =F3*$A$1 -> 6.9314417 | H3: =PI()*G3^2 -> 150.93745 | I3: =K3/J3 -> 659.04777 | J3: 6851.429 | K3: 4515419 | L3: =H3*I3 -> 99474.993 | M3: =MIN(K3,L3) -> 99474.993 | N3: . | O3: =P3/J3 -> 323.74122 | P3: 2218090 | Q3: =H3*O3 -> 48864.676 | R3: =MIN(Q3,P3) -> 48864.676
A4: Austin | B4: 62.91075 | C4: 76.75675 | D4: =C4*$A$1*1000 -> 12792.792 | E4: ='Interval Circuities'!B4 -> 1.4404459 | F4: =B4/E4 -> 43.674498 | G4: =F4*$A$1 -> 7.279083 | H4: =PI()*G4^2 -> 166.45744 | I4: =K4/J4 -> 1005.7321 | J4: 1354.651 | K4: 1362416 | L4: =H4*I4 -> 167411.59 | M4: =MIN(K4,L4) -> 167411.59 | N4: . | O4: =P4/J4 -> 484.29964 | P4: 656057 | Q4: =H4*O4 -> 80615.278 | R4: =MIN(Q4,P4) -> 80615.278
A5: Baltimore2 | B5: 59.8115 | C5: 68.62625 | D5: =C5*$A$1*1000 -> 11437.708 | E5: ='Interval Circuities'!B5 -> 1.382295 | F5: =B5/E5 -> 43.269708 | G5: =F5*$A$1 -> 7.211618 | H5: =PI()*G5^2 -> 163.38617 | I5: =K5/J5 -> 1186.6066 | J5: 1857.1133 | K5: 2203663 | L5: =H5*I5 -> 193875.12 | M5: =MIN(K5,L5) -> 193875.12 | N5: . | O5: =P5/J5 -> 604.12037 | P5: 1121920 | Q5: =H5*O5 -> 98704.915 | R5: =MIN(Q5,P5) -> 98704.915
A6: Boston | B6: 53.613 | C6: 62.8705 | D6: =C6*$A$1*1000 -> 10478.417 | E6: ='Interval Circuities'!B6 -> 1.3221708 | F6: =B6/E6 -> 40.549224 | G6: =F6*$A$1 -> 6.758204 | H6: =PI()*G6^2 -> 143.48697 | I6: =K6/J6 -> 861.67002 | J6: 4852.2275 | K6: 4181019 | L6: =H6*I6 -> 123638.42 | M6: =MIN(K6,L6) -> 123638.42 | N6: . | O6: =P6/J6 -> 598.22978 | P6: =2341938+286024+61431+22699+190655 -> 2902747 | Q6: =H6*O6 -> 85838.179 | R6: =MIN(Q6,P6) -> 85838.179
A7: Buffalo | B7: 63.434 | C7: 70.23625 | D7: =C7*$A$1*1000 -> 11706.042 | E7: ='Interval Circuities'!B7 -> 1.2726128 | F7: =B7/E7 -> 49.845483 | G7: =F7*$A$1 -> 8.3075804 | H7: =PI()*G7^2 -> 216.81982 | I7: =K7/J7 -> 951.10926 | J7: 984.01524 | K7: 935906 | L7: =H7*I7 -> 206219.34 | M7: =MIN(K7,L7) -> 206219.34 | N7: . | O7: =P7/J7 -> 476.95704 | P7: 469333 | Q7: =H7*O7 -> 103413.74 | R7: =MIN(Q7,P7) -> 103413.74
A8: Charlotte | B8: 61.2605 | C8: 70.79975 | D8: =C8*$A$1*1000 -> 11799.958 | E8: ='Interval Circuities'!B8 -> 1.3548292 | F8: =B8/E8 -> 45.2164 | G8: =F8*$A$1 -> 7.5360667 | H8: =PI()*G8^2 -> 178.41828 | I8: =K8/J8 -> 650.59688 | J8: 1920.4549 | K8: 1249442 | L8: =H8*I8 -> 116078.38 | M8: =MIN(K8,L8) -> 116078.38 | N8: . | O8: =P8/J8 -> 424.53014 | P8: 815291 | Q8: =H8*O8 -> 75743.936 | R8: =MIN(Q8,P8) -> 75743.936
A9: Chicago | B9: 49.266 | C9: 60.49575 | D9: =C9*$A$1*1000 -> 10082.625 | E9: ='Interval Circuities'!B9 -> 1.3236002 | F9: =B9/E9 -> 37.221209 | G9: =F9*$A$1 -> 6.2035348 | H9: =PI()*G9^2 -> 120.90056 | I9: =K9/J9 -> 1360.6187 | J9: 6326.6863 | K9: 8608208 | L9: =H9*I9 -> 164499.57 | M9: =MIN(K9,L9) -> 164499.57 | N9: . | O9: =P9/J9 -> 661.5068 | P9: 4185146 | Q9: =H9*O9 -> 79976.542 | R9: =MIN(Q9,P9) -> 79976.542
A10: Cincinnati | B10: 66.8955 | C10: 72.5305 | D10: =C10*$A$1*1000 -> 12088.417 | E10: ='Interval Circuities'!B10 -> 1.4101242 | F10: =B10/E10 -> 47.439437 | G10: =F10*$A$1 -> 7.9065728 | H10: =PI()*G10^2 -> 196.39319 | I10: =K10/J10 -> 796.39106 | J10: 2040.2376 | K10: 1624827 | L10: =H10*I10 -> 156405.78 | M10: =MIN(K10,L10) -> 156405.78 | N10: . | O10: =P10/J10 -> 464.30965 | P10: 947302 | Q10: =H10*O10 -> 91187.251 | R10: =MIN(Q10,P10) -> 91187.251
A11: Cleveland | B11: 66.332 | C11: 73.0135 | D11: =C11*$A$1*1000 -> 12168.917 | E11: ='Interval Circuities'!B11 -> 1.2785144 | F11: =B11/E11 -> 51.882089 | G11: =F11*$A$1 -> 8.6470149 | H11: =PI()*G11^2 -> 234.8996 | I11: =K11/J11 -> 890.6046 | J11: 1999.3979 | K11: 1780673 | L11: =H11*I11 -> 209202.67 | M11: =MIN(K11,L11) -> 209202.67 | N11: . | O11: =P11/J11 -> 475.21255 | P11: 950139 | Q11: =H11*O11 -> 111627.24 | R11: =MIN(Q11,P11) -> 111627.24
A12: Columbus | B12: 73.1745 | C12: 79.7755 | D12: =C12*$A$1*1000 -> 13295.917 | E12: ='Interval Circuities'!B12 -> 1.3249637 | F12: =B12/E12 -> 55.22755 | G12: =F12*$A$1 -> 9.2045916 | H12: =PI()*G12^2 -> 266.16989 | I12: =K12/J12 -> 1034.7499 | J12: 1322.0924 | K12: 1368035 | L12: =H12*I12 -> 275419.27 | M12: =MIN(K12,L12) -> 275419.27 | N12: . | O12: =P12/J12 -> 599.7841 | P12: 792970 | Q12: =H12*O12 -> 159644.47 | R12: =MIN(Q12,P12) -> 159644.47
A13: Dallas-Fort Worth | B13: 53.89475 | C13: 63.39375 | D13: =C13*$A$1*1000 -> 10565.625 | E13: ='Interval Circuities'!B13 -> 1.3824701 | F13: =B13/E13 -> 38.984387 | G13: =F13*$A$1 -> 6.4973978 | H13: =PI()*G13^2 -> 132.62604 | I13: =K13/J13 -> 1111.537 | J13: 4607.9365 | K13: 5121892 | L13: =H13*I13 -> 147418.75 | M13: =MIN(K13,L13) -> 147418.75 | N13: . | O13: =P13/J13 -> 577.14685 | P13: 2659456 | Q13: =H13*O13 -> 76544.698 | R13: =MIN(Q13,P13) -> 76544.698
A14: Denver | B14: 54.78025 | C14: 64.11825 | D14: =C14*$A$1*1000 -> 10686.375 | E14: ='Interval Circuities'!B14 -> 1.3957009 | F14: =B14/E14 -> 39.249277 | G14: =F14*$A$1 -> 6.5415461 | H14: =PI()*G14^2 -> 134.43449 | I14: =K14/J14 -> 1372.3806 | J14: 1729.9887 | K14: 2374203 | L14: =H14*I14 -> 184495.28 | M14: =MIN(K14,L14) -> 184495.28 | N14: . | O14: =P14/J14 -> 661.20142 | P14: 1143871 | Q14: =H14*O14 -> 88888.273 | R14: =MIN(Q14,P14) -> 88888.273
A15: Detroit | B15: 57.5575 | C15: 65.1245 | D15: =C15*$A$1*1000 -> 10854.083 | E15: ='Interval Circuities'!B15 -> 1.3026209 | F15: =B15/E15 -> 44.185919 | G15: =F15*$A$1 -> 7.3643199 | H15: =PI()*G15^2 -> 170.37865 | I15: =K15/J15 -> 1078.2087 | J15: 3463.2348 | K15: 3734090 | L15: =H15*I15 -> 183703.75 | M15: =MIN(K15,L15) -> 183703.75 | N15: . | O15: =P15/J15 -> 492.33307 | P15: 1705065 | Q15: =H15*O15 -> 83883.042 | R15: =MIN(Q15,P15) -> 83883.042
A16: Grand Rapids | B16: 72.65 | C16: 79.78 | D16: =C16*$A$1*1000 -> 13296.667 | E16: ='Interval Circuities'!B16 -> 1.3210529 | F16: =B16/E16 -> 54.994015 | G16: =F16*$A$1 -> 9.1656691 | H16: =PI()*G16^2 -> 263.9236 | I16: =K16/J16 -> 784.29738 | J16: 726.68227 | K16: 569935 | L16: =H16*I16 -> 206994.58 | M16: =MIN(K16,L16) -> 206994.58 | N16: . | O16: =P16/J16 -> 733.43333 | P16: =347964+52598+97277+35134 -> 532973 | Q16: =H16*O16 -> 193570.36 | R16: =MIN(Q16,P16) -> 193570.36
A17: Hampton Roads | B17: 63.39375 | C17: 72.08775 | D17: =C17*$A$1*1000 -> 12014.625 | E17: ='Interval Circuities'!B17 -> 1.4040824 | F17: =B17/E17 -> 45.149593 | G17: =F17*$A$1 -> 7.5249322 | H17: =PI()*G17^2 -> 177.89144 | I17: =K17/J17 -> 1078.402 | J17: 1334.9993 | K17: 1439666 | L17: =H17*I17 -> 191838.49 | M17: =MIN(K17,L17) -> 191838.49 | N17: . | O17: =P17/J17 -> 477.00023 | P17: 636795 | Q17: =H17*O17 -> 84854.26 | R17: =MIN(Q17,P17) -> 84854.26
A18: Hartford | B18: 65.96975 | C18: 73.8185 | D18: =C18*$A$1*1000 -> 12303.083 | E18: ='Interval Circuities'!B18 -> 1.3288885 | F18: =B18/E18 -> 49.642801 | G18: =F18*$A$1 -> 8.2738002 | H18: =PI()*G18^2 -> 215.06014 | I18: =K18/J18 -> 691.70596 | J18: 1337.0696 | K18: 924859 | L18: =H18*I18 -> 148758.38 | M18: =MIN(K18,L18) -> 148758.38 | N18: . | O18: =P18/J18 -> 423.74459 | P18: 566576 | Q18: =H18*O18 -> 91130.571 | R18: =MIN(Q18,P18) -> 91130.571
A19: Honolulu | B19: 61.7435 | C19: 74.74425 | D19: =C19*$A$1*1000 -> 12457.375 | E19: ='Interval Circuities'!B19 -> 1.4170125 | F19: =B19/E19 -> 43.57301 | G19: =F19*$A$1 -> 7.2621683 | H19: =PI()*G19^2 -> 165.68473 | I19: =K19/J19 -> 1820.7094 | J19: 440.73975 | K19: 802459 | L19: =H19*I19 -> 301663.75 | M19: =MIN(K19,L19) -> 301663.75 | N19: . | O19: =P19/J19 -> 810.41931 | P19: 357184 | Q19: =H19*O19 -> 134274.11 | R19: =MIN(Q19,P19) -> 134274.11
A20: Houston | B20: 58.40275 | C20: 69.59225 | D20: =C20*$A$1*1000 -> 11598.708 | E20: ='Interval Circuities'!B20 -> 1.411267 | F20: =B20/E20 -> 41.383205 | G20: =F20*$A$1 -> 6.8972008 | H20: =PI()*G20^2 -> 149.44989 | I20: =K20/J20 -> 1149.9995 | J20: 4299.421 | K20: 4944332 | L20: =H20*I20 -> 171867.3 | M20: =MIN(K20,L20) -> 171867.3 | N20: . | O20: =P20/J20 -> 527.05888 | P20: 2266048 | Q20: =H20*O20 -> 78768.894 | R20: =MIN(Q20,P20) -> 78768.894
A21: Indianapolis | B21: 54.53875 | C21: 64.44025 | D21: =C21*$A$1*1000 -> 10740.042 | E21: ='Interval Circuities'!B21 -> 1.330739 | F21: =B21/E21 -> 40.983806 | G21: =F21*$A$1 -> 6.8306344 | H21: =PI()*G21^2 -> 146.57907 | I21: =K21/J21 -> 813.78264 | J21: 1827.8628 | K21: 1487483 | L21: =H21*I21 -> 119283.5 | M21: =MIN(K21,L21) -> 119283.5 | N21: . | O21: =P21/J21 -> 435.24164 | P21: 795562 | Q21: =H21*O21 -> 63797.314 | R21: =MIN(Q21,P21) -> 63797.314
A22: Inland Empire2 | B22: 60.17375 | C22: 67.82125 | D22: =C22*$A$1*1000 -> 11303.542 | E22: ='Interval Circuities'!B22 -> 1.3734377 | F22: =B22/E22 -> 43.812507 | G22: =F22*$A$1 -> 7.3020844 | H22: =PI()*G22^2 -> 167.51109 | I22: =K22/J22 -> 1369.2709 | J22: 1411.4562 | K22: 1932666 | L22: =H22*I22 -> 229368.07 | M22: =MIN(K22,L22) -> 229368.07 | N22: . | O22: =P22/J22 -> 777.85338 | P22: 1097906 | Q22: =H22*O22 -> 130299.07 | R22: =MIN(Q22,P22) -> 130299.07
A23: Jacksonville | B23: 66.332 | C23: 74.18075 | D23: =C23*$A$1*1000 -> 12363.458 | E23: ='Interval Circuities'!B23 -> 1.3923353 | F23: =B23/E23 -> 47.640825 | G23: =F23*$A$1 -> 7.9401374 | H23: =PI()*G23^2 -> 198.06417 | I23: =K23/J23 -> 775.48585 | J23: 1373.615 | K23: 1065219 | L23: =H23*I23 -> 153595.96 | M23: =MIN(K23,L23) -> 153595.96 | N23: . | O23: =P23/J23 -> 393.33583 | P23: 540292 | Q23: =H23*O23 -> 77905.734 | R23: =MIN(Q23,P23) -> 77905.734
A24: Kansas City | B24: 63.434 | C24: 69.552 | D24: =C24*$A$1*1000 -> 11592 | E24: ='Interval Circuities'!B24 -> 1.347678 | F24: =B24/E24 -> 47.069108 | G24: =F24*$A$1 -> 7.8448514 | H24: =PI()*G24^2 -> 193.33893 | I24: =K24/J24 -> 865.4748 | J24: 1755.5878 | K24: 1519417 | L24: =H24*I24 -> 167329.97 | M24: =MIN(K24,L24) -> 167329.97 | N24: . | O24: =P24/J24 -> 528.94933 | P24: 928617 | Q24: =H24*O24 -> 102266.5 | R24: =MIN(Q24,P24) -> 102266.5
A25: Las Vegas | B25: 59.52975 | C25: 69.83375 | D25: =C25*$A$1*1000 -> 11638.958 | E25: ='Interval Circuities'!B25 -> 1.3286383 | F25: =B25/E25 -> 44.805085 | G25: =F25*$A$1 -> 7.4675141 | H25: =PI()*G25^2 -> 175.18704 | I25: =K25/J25 -> 1746.9194 | J25: 1079.6211 | K25: 1886011 | L25: =H25*I25 -> 306037.64 | M25: =MIN(K25,L25) -> 306037.64 | N25: . | O25: =P25/J25 -> 779.9931 | P25: 842097 | Q25: =H25*O25 -> 136644.68 | R25: =MIN(Q25,P25) -> 136644.68
A26: Los Angeles2 | B26: 52.92875 | C26: 66.0905 | D26: =C26*$A$1*1000 -> 11015.083 | E26: ='Interval Circuities'!B26 -> 1.3492228 | F26: =B26/E26 -> 39.229066 | G26: =F26*$A$1 -> 6.5381776 | H26: =PI()*G26^2 -> 134.29607 | I26: =K26/J26 -> 2702.4638 | J26: 4496.266 | K26: 12150996 | L26: =H26*I26 -> 362930.26 | M26: =MIN(K26,L26) -> 362930.26 | N26: . | O26: =P26/J26 -> 1191.653 | P26: 5357989 | Q26: =H26*O26 -> 160034.32 | R26: =MIN(Q26,P26) -> 160034.32
A27: Louisville | B27: 63.47425 | C27: 71.28275 | D27: =C27*$A$1*1000 -> 11880.458 | E27: ='Interval Circuities'!B27 -> 1.4152337 | F27: =B27/E27 -> 44.85072 | G27: =F27*$A$1 -> 7.4751201 | H27: =PI()*G27^2 -> 175.54409 | I27: =K27/J27 -> 787.67763 | J27: 1234.7005 | K27: 972546 | L27: =H27*I27 -> 138272.15 | M27: =MIN(K27,L27) -> 138272.15 | N27: . | O27: =P27/J27 -> 450.3594 | P27: 556059 | Q27: =H27*O27 -> 79057.933 | R27: =MIN(Q27,P27) -> 79057.933
A28: Memphis | B28: 67.41875 | C28: 75.14675 | D28: =C28*$A$1*1000 -> 12524.458 | E28: ='Interval Circuities'!B28 -> 1.383671 | F28: =B28/E28 -> 48.724553 | G28: =F28*$A$1 -> 8.1207589 | H28: =PI()*G28^2 -> 207.17775 | I28: =K28/J28 -> 823.01438 | J28: 1288.0225 | K28: 1060061 | L28: =H28*I28 -> 170510.27 | M28: =MIN(K28,L28) -> 170510.27 | N28: . | O28: =P28/J28 -> 431.02199 | P28: 555166 | Q28: =H28*O28 -> 89298.165 | R28: =MIN(Q28,P28) -> 89298.165
... A32: New Orleans | B32: 56.14875 | C32: 67.137 | D32: =C32*$A$1*1000 -> 11189.5 | E32: ='Interval Circuities'!B32 -> 1.4163225 | F32: =B32/E32 -> 39.644042 | G32: =F32*$A$1 -> 6.6073403 | H32: =PI()*G32^2 -> 137.15234 | I32: =K32/J32 -> 1381.8089 | J32: 651.10521 | K32: 899703 | L32: =H32*I32 -> 189518.33 | M32: =MIN(K32,L32) -> 189518.33 | N32: . | O32: =P32/J32 -> 707.13764 | P32: 460421 | Q32: =H32*O32 -> 96985.582 | R32: =MIN(Q32,P32) -> 96985.582
A33: New York | B33: 55.1425 | C33: 67.66025 | D33: =C33*$A$1*1000 -> 11276.708 | E33: ='Interval Circuities'!B33 -> 1.3157627 | F33: =B33/E33 -> 41.909151 | G33: =F33*$A$1 -> 6.9848585 | H33: =PI()*G33^2 -> 153.2728 | I33: =K33/J33 -> 2053.6407 | J33: 8935.9814 | K33: 18351295 | L33: =H33*I33 -> 314767.27 | M33: =MIN(K33,L33) -> 314767.27 | N33: . | O33: =P33/J33 -> 914.58136 | P33: =7737401+435281 -> 8172682 | Q33: =H33*O33 -> 140180.45 | R33: =MIN(Q33,P33) -> 140180.45
A34: Oklahoma City | B34: 69.02875 | C34: 75.95175 | D34: =C34*$A$1*1000 -> 12658.625 | E34: ='Interval Circuities'!B34 -> 1.3330076 | F34: =B34/E34 -> 51.784215 | G34: =F34*$A$1 -> 8.6307025 | H34: =PI()*G34^2 -> 234.01418 | I34: =K34/J34 -> 810.03968 | J34: 1063.5343 | K34: 861505 | L34: =H34*I34 -> 189560.77 | M34: =MIN(K34,L34) -> 189560.77 | N34: . | O34: =P34/J34 -> 452.14902 | P34: 480876 | Q34: =H34*O34 -> 105809.28 | R34: =MIN(Q34,P34) -> 105809.28
A35: Orlando | B35: 58.16125 | C35: 69.069 | D35: =C35*$A$1*1000 -> 11511.5 | E35: ='Interval Circuities'!B35 -> 1.4073454 | F35: =B35/E35 -> 41.32692 | G35: =F35*$A$1 -> 6.88782 | H35: =PI()*G35^2 -> 149.04364 | I35: =K35/J35 -> 975.77759 | J35: 1548.0126 | K35: 1510516 | L35: =H35*I35 -> 145433.44 | M35: =MIN(K35,L35) -> 145433.44 | N35: . | O35: =P35/J35 -> 606.6656 | P35: 939126 | Q35: =H35*O35 -> 90419.651 | R35: =MIN(Q35,P35) -> 90419.651
A36: Philadelphia | B36: 59.77125 | C36: 68.06275 | D36: =C36*$A$1*1000 -> 11343.792 | E36: ='Interval Circuities'!B36 -> 1.2908067 | F36: =B36/E36 -> 46.305347 | G36: =F36*$A$1 -> 7.7175578 | H36: =PI()*G36^2 -> 187.11545 | I36: =K36/J36 -> 1060.3785 | J36: 5131.7215 | K36: 5441567 | L36: =H36*I36 -> 198413.2 | M36: =MIN(K36,L36) -> 198413.2 | N36: . | O36: =P36/J36 -> 500.0207 | P36: 2565967 | Q36: =H36*O36 -> 93561.601 | R36: =MIN(Q36,P36) -> 93561.601
A37: Phoenix | B37: 63.756 | C37: 70.47775 | D37: =C37*$A$1*1000 -> 11746.292 | E37: ='Interval Circuities'!B37 -> 1.3444279 | F37: =B37/E37 -> 47.422401 | G37: =F37*$A$1 -> 7.9037335 | H37: =PI()*G37^2 -> 196.25216 | I37: =K37/J37 -> 1222.0876 | J37: 2969.6022 | K37: 3629114 | L37: =H37*I37 -> 239837.34 | M37: =MIN(K37,L37) -> 239837.34 | N37: . | O37: =P37/J37 -> 553.72771 | P37: 1644351 | Q37: =H37*O37 -> 108670.26 | R37: =MIN(Q37,P37) -> 108670.26
A38: Pittsburgh | B38: 68.46525 | C38: 76.83725 | D38: =C38*$A$1*1000 -> 12806.208 | E38: ='Interval Circuities'!B38 -> 1.4115605 | F38: =B38/E38 -> 48.503234 | G38: =F38*$A$1 -> 8.0838723 | H38: =PI()*G38^2 -> 205.29991 | I38: =K38/J38 -> 739.57535 | J38: 2344.3899 | K38: 1733853 | L38: =H38*I38 -> 151834.75 | M38: =MIN(K38,L38) -> 151834.75 | N38: . | O38: =P38/J38 -> 455.62643 | P38: 1068166 | Q38: =H38*O38 -> 93540.065 | R38: =MIN(Q38,P38) -> 93540.065
A39: Portland | B39: 60.9385 | C39: 71.44375 | D39: =C39*$A$1*1000 -> 11907.292 | E39: ='Interval Circuities'!B39 -> 1.5301277 | F39: =B39/E39 -> 39.825762 | G39: =F39*$A$1 -> 6.6376269 | H39: =PI()*G39^2 -> 138.41258 | I39: =K39/J39 -> 1362.076 | J39: 1358.146 | K39: 1849898 | L39: =H39*I39 -> 188528.44 | M39: =MIN(K39,L39) -> 188528.44 | N39: . | O39: =P39/J39 -> 697.50822 | P39: 947318 | Q39: =H39*O39 -> 96543.91 | R39: =MIN(Q39,P39) -> 96543.91
A40: Providence | B40: 61.54225 | C40: 68.06275 | D40: =C40*$A$1*1000 -> 11343.792 | E40: ='Interval Circuities'!B40 -> 1.3413795 | F40: =B40/E40 -> 45.879818 | G40: =F40*$A$1 -> 7.6466364 | H40: =PI()*G40^2 -> 183.69222 | I40: =K40/J40 -> 843.65596 | J40: 1411.6607 | K40: 1190956 | L40: =H40*I40 -> 154973.03 | M40: =MIN(K40,L40) -> 154973.03 | N40: . | O40: =P40/J40 -> 450.46446 | P40: 635903 | Q40: =H40*O40 -> 82746.815 | R40: =MIN(Q40,P40) -> 82746.815
A41: Raleigh | B41: 67.57975 | C41: 75.46875 | D41: =C41*$A$1*1000 -> 12578.125 | E41: ='Interval Circuities'!B41 -> 1.359956 | F41: =B41/E41 -> 49.6926 | G41: =F41*$A$1 -> 8.2821 | H41: =PI()*G41^2 -> 215.49183 | I41: =K41/J41 -> 659.39427 | J41: 1341.9756 | K41: 884891 | L41: =H41*I41 -> 142094.08 | M41: =MIN(K41,L41) -> 142094.08 | N41: . | O41: =P41/J41 -> 518.08246 | P41: =438888+235541+20825 -> 695254 | Q41: =H41*O41 -> 111642.54 | R41: =MIN(Q41,P41) -> 111642.54
A42: Rochester, NY | B42: 63.595 | C42: 70.84 | D42: =C42*$A$1*1000 -> 11806.667 | E42: ='Interval Circuities'!B42 -> 1.3054372 | F42: =B42/E42 -> 48.71548 | G42: =F42*$A$1 -> 8.1192466 | H42: =PI()*G42^2 -> 207.10059 | I42: =K42/J42 -> 857.4454 | J42: 840.37071 | K42: 720572 | L42: =H42*I42 -> 177577.45 | M42: =MIN(K42,L42) -> 177577.45 | N42: . | O42: =P42/J42 -> 542.26664 | P42: =430223+17339+8143 -> 455705 | Q42: =H42*O42 -> 112303.74 | R42: =MIN(Q42,P42) -> 112303.74
A43: Sacramento | B43: 56.87325 | C43: 65.688 | D43: =C43*$A$1*1000 -> 10948 | E43: ='Interval Circuities'!B43 -> 1.4338793 | F43: =B43/E43 -> 39.663903 | G43: =F43*$A$1 -> 6.6106506 | H43: =PI()*G43^2 -> 137.2898 | I43: =K43/J43 -> 1413.0148 | J43: 1219.8273 | K43: 1723634 | L43: =H43*I43 -> 193992.52 | M43: =MIN(K43,L43) -> 193992.52 | N43: . | O43: =P43/J43 -> 570.37419 | P43: 695758 | Q43: =H43*O43 -> 78306.559 | R43: =MIN(Q43,P43) -> 78306.559
...

Sheet 2010-20
A1: =2/6 -> 0.33333333 | B1: Network Speed (congested) [km/h] | C1: Network Speed (freeflow) [km/h] | D1: 20 Minute Distance | E1: 20 Minute Circuity [ ] | F1: Average Airline Speed [km/h] | G1: Airline Radius [km] | H1: Area covered in $A$1$ hrs [km2] | I1: Urbanized area density [people/km2] | J1: Area [km2] | K1: Population | L1: Accessibility | M1: MinPA,P | N1: . | O1: Employment Density | P1: Employment | Q1: Employment Accessibility | R1: Min EA, E
